[MFLOG|0|2025-04-17T18:40:07.832676Z|runtime|30f8cfcd-d62e-429a-8b44-7608be5df83f]<flow TrainingFlow step tune_model> failed:
[MFLOG|0|2025-04-17T18:40:07.867698Z|runtime|bb492540-7304-4644-afa7-a91de2814d85]    Internal error
[MFLOG|0|2025-04-17T18:40:07.868582Z|runtime|9379e5de-f646-4e7d-b5b6-af483ba279c1]Traceback (most recent call last):
[MFLOG|0|2025-04-17T18:40:07.868653Z|runtime|6a5a4e20-1a0c-4c07-81d0-4b2ebdf9e38d]  File "/opt/anaconda3/envs/mlops/lib/python3.12/site-packages/metaflow/cli.py", line 611, in main
[MFLOG|0|2025-04-17T18:40:07.868680Z|runtime|857d34c0-3e2b-4a31-8a16-1a63d6a71c3a]    start(auto_envvar_prefix="METAFLOW", obj=state)
[MFLOG|0|2025-04-17T18:40:07.868715Z|runtime|b22e384a-10c7-4117-96ab-33a13126ef22]  File "/opt/anaconda3/envs/mlops/lib/python3.12/site-packages/metaflow/_vendor/click/core.py", line 829, in __call__
[MFLOG|0|2025-04-17T18:40:07.868745Z|runtime|c6eba9b4-4df9-447b-b917-efd82e5b4334]    return self.main(args, kwargs)
[MFLOG|0|2025-04-17T18:40:07.975302Z|runtime|30f9f9d4-5b23-4b63-91ce-a5db3fa01930]           ^^^^^^^^^^^^^^^^^^^^^^^^^^
[MFLOG|0|2025-04-17T18:40:07.975431Z|runtime|b8cfd72a-703b-4bea-b15c-0d8f0b1abebc]  File "/opt/anaconda3/envs/mlops/lib/python3.12/site-packages/metaflow/_vendor/click/core.py", line 782, in main
[MFLOG|0|2025-04-17T18:40:07.975466Z|runtime|fbbe490a-5ab4-40b2-bfb2-ee1debb56b3b]    rv = self.invoke(ctx)
[MFLOG|0|2025-04-17T18:40:07.975487Z|runtime|6a1d5d67-cd22-44bd-8815-b5d92b9a5b68]         ^^^^^^^^^^^^^^^^
[MFLOG|0|2025-04-17T18:40:07.975511Z|runtime|20ef7417-e2ec-42f3-81e3-55dbacac3e47]  File "/opt/anaconda3/envs/mlops/lib/python3.12/site-packages/metaflow/cli_components/utils.py", line 69, in invoke
[MFLOG|0|2025-04-17T18:40:07.975530Z|runtime|116b41fd-7eb0-4d1b-8517-75b7c533a041]    return _process_result(sub_ctx.command.invoke(sub_ctx))
[MFLOG|0|2025-04-17T18:40:07.975549Z|runtime|913cff24-7ee6-4ba3-a5b2-81b798909364]                           ^^^^^^^^^^^^^^^^^^^^^^^^^^^^^^^
[MFLOG|0|2025-04-17T18:40:07.975570Z|runtime|edc291a1-0ac2-4508-8d81-1cbaaea31e4f]  File "/opt/anaconda3/envs/mlops/lib/python3.12/site-packages/metaflow/_vendor/click/core.py", line 1066, in invoke
[MFLOG|0|2025-04-17T18:40:07.975590Z|runtime|7d0d1c5b-fa43-48f5-9243-a29ea02aa297]    return ctx.invoke(self.callback, ctx.params)
[MFLOG|0|2025-04-17T18:40:07.975609Z|runtime|65afe3da-8e11-41ab-b49f-9bc399e847f5]           ^^^^^^^^^^^^^^^^^^^^^^^^^^^^^^^^^^^^^^^
[MFLOG|0|2025-04-17T18:40:07.975627Z|runtime|38084ac2-ace2-4399-8a4a-9e175f96616f]  File "/opt/anaconda3/envs/mlops/lib/python3.12/site-packages/metaflow/_vendor/click/core.py", line 610, in invoke
[MFLOG|0|2025-04-17T18:40:07.975650Z|runtime|bb746af9-a658-4cbf-bea5-c85354d181e0]    return callback(args, kwargs)
[MFLOG|0|2025-04-17T18:40:07.975673Z|runtime|517e8cc4-688a-4219-a108-96746528a0c7]           ^^^^^^^^^^^^^^^^^^^^^^^^^
[MFLOG|0|2025-04-17T18:40:07.975714Z|runtime|93d961b0-9c48-4deb-a9bd-d5ea18fe55d0]  File "/opt/anaconda3/envs/mlops/lib/python3.12/site-packages/metaflow/tracing/__init__.py", line 27, in wrapper_func
[MFLOG|0|2025-04-17T18:40:07.975735Z|runtime|2e45f677-e465-4bf2-8c49-8bb962ce3608]    return func(args, kwargs)
[MFLOG|0|2025-04-17T18:40:07.975759Z|runtime|dc3c829c-2bb6-4689-8bf7-320e8d7549ed]           ^^^^^^^^^^^^^^^^^^^^^
[MFLOG|0|2025-04-17T18:40:07.975777Z|runtime|5e1349f8-6013-4c93-920a-d0e9218540f8]  File "/opt/anaconda3/envs/mlops/lib/python3.12/site-packages/metaflow/_vendor/click/decorators.py", line 21, in new_func
[MFLOG|0|2025-04-17T18:40:07.975798Z|runtime|7ddf45ae-869e-4a99-b8bf-f7a63daf6ad0]    return f(get_current_context(), args, kwargs)
[MFLOG|0|2025-04-17T18:40:07.975816Z|runtime|603765e0-fbc5-427c-986d-8871aa697473]           ^^^^^^^^^^^^^^^^^^^^^^^^^^^^^^^^^^^^^^^^^
[MFLOG|0|2025-04-17T18:40:07.975834Z|runtime|1c1b7f53-3e26-4831-81cb-5ffee7b418f3]  File "/opt/anaconda3/envs/mlops/lib/python3.12/site-packages/metaflow/cli_components/step_cmd.py", line 167, in step
[MFLOG|0|2025-04-17T18:40:07.975856Z|runtime|a9ebd328-db0e-45d4-8ab8-7ab57141e6c9]    task.run_step(
[MFLOG|0|2025-04-17T18:40:07.975875Z|runtime|e3421c84-3764-49c8-a9a4-185d6d2a8fec]  File "/opt/anaconda3/envs/mlops/lib/python3.12/site-packages/metaflow/task.py", line 672, in run_step
[MFLOG|0|2025-04-17T18:40:07.975892Z|runtime|d9baef43-864e-4332-846a-9aca06e90611]    self._exec_step_function(step_func)
[MFLOG|0|2025-04-17T18:40:07.975911Z|runtime|e7c84aaf-6e18-4ffe-be26-d791dddeab50]  File "/opt/anaconda3/envs/mlops/lib/python3.12/site-packages/metaflow/task.py", line 62, in _exec_step_function
[MFLOG|0|2025-04-17T18:40:07.975928Z|runtime|42acd84e-c4ae-495f-bf8d-f6383374b25e]    step_function()
[MFLOG|0|2025-04-17T18:40:07.975945Z|runtime|0a266ed8-35e6-4a5c-98fd-345996ec07c7]  File "/Users/jahnavipaliwal/Desktop/ML_Ops/MLOps/Labs/Lab6/src/trainingflow.py", line 34, in tune_model
[MFLOG|0|2025-04-17T18:40:07.975965Z|runtime|8ebbab30-d052-453f-9a27-a23f144592ad]    grid_search.fit(self.X, self.y)
[MFLOG|0|2025-04-17T18:40:07.975982Z|runtime|29a354ee-ccf4-4056-9271-a7048f83d0ea]  File "/opt/anaconda3/envs/mlops/lib/python3.12/site-packages/sklearn/base.py", line 1473, in wrapper
[MFLOG|0|2025-04-17T18:40:07.976000Z|runtime|74b0881b-3221-413e-9f1b-470b853ec8d8]    return fit_method(estimator, args, kwargs)
[MFLOG|0|2025-04-17T18:40:07.976016Z|runtime|655f757c-a3cc-4af5-9b70-ac18b18cf30d]           ^^^^^^^^^^^^^^^^^^^^^^^^^^^^^^^^^^^^^^
[MFLOG|0|2025-04-17T18:40:07.976033Z|runtime|3e809f83-fb94-42c5-b80f-5b8ab40ae34e]  File "/opt/anaconda3/envs/mlops/lib/python3.12/site-packages/sklearn/model_selection/_search.py", line 1018, in fit
[MFLOG|0|2025-04-17T18:40:07.976050Z|runtime|73bd6503-c3a9-4f8a-abd8-4b03e79ec13b]    self._run_search(evaluate_candidates)
[MFLOG|0|2025-04-17T18:40:07.976067Z|runtime|fbbb6986-ee48-4c7c-b65b-cb6ff6503522]  File "/opt/anaconda3/envs/mlops/lib/python3.12/site-packages/sklearn/model_selection/_search.py", line 1572, in _run_search
[MFLOG|0|2025-04-17T18:40:07.976084Z|runtime|4f87483f-9be1-4a3b-b7a2-9b655521bff0]    evaluate_candidates(ParameterGrid(self.param_grid))
[MFLOG|0|2025-04-17T18:40:07.976101Z|runtime|87617603-0f55-4333-a704-6521d6fc8713]  File "/opt/anaconda3/envs/mlops/lib/python3.12/site-packages/sklearn/model_selection/_search.py", line 995, in evaluate_candidates
[MFLOG|0|2025-04-17T18:40:07.976123Z|runtime|12077bb1-a9b7-4921-81f1-89e72bcba38c]    _warn_or_raise_about_fit_failures(out, self.error_score)
[MFLOG|0|2025-04-17T18:40:07.976139Z|runtime|18495c6e-a192-4a78-b8ea-ef0aa2ec6aa6]  File "/opt/anaconda3/envs/mlops/lib/python3.12/site-packages/sklearn/model_selection/_validation.py", line 529, in _warn_or_raise_about_fit_failures
[MFLOG|0|2025-04-17T18:40:07.976158Z|runtime|aead9569-a1da-4797-933e-bc9040ad1b76]    raise ValueError(all_fits_failed_message)
[MFLOG|0|2025-04-17T18:40:07.976176Z|runtime|1f2090cc-2ded-42f9-9ed1-f987bb87b6e4]ValueError: 
[MFLOG|0|2025-04-17T18:40:07.976196Z|runtime|2322ad71-63dd-4f11-b4a8-689903a345e9]All the 12 fits failed.
[MFLOG|0|2025-04-17T18:40:07.976214Z|runtime|bb4af61f-0f9e-4924-813e-bbc109c856a3]It is very likely that your model is misconfigured.
[MFLOG|0|2025-04-17T18:40:07.976234Z|runtime|b69ea378-747c-42c8-86d3-89975d64047c]You can try to debug the error by setting error_score='raise'.
[MFLOG|0|2025-04-17T18:40:07.976252Z|runtime|37665492-2b25-47f4-a8b6-c989c9f6d631]
[MFLOG|0|2025-04-17T18:40:07.976271Z|runtime|9e58fbf1-6dc0-4cc4-a193-e81fa7c5aabe]Below are more details about the failures:
[MFLOG|0|2025-04-17T18:40:07.976288Z|runtime|74284bc8-92a5-48c3-94db-88369bf25b02]--------------------------------------------------------------------------------
[MFLOG|0|2025-04-17T18:40:07.976306Z|runtime|97869bc1-d442-4dbd-b6e8-72517fff08f8]12 fits failed with the following error:
[MFLOG|0|2025-04-17T18:40:07.976322Z|runtime|6c449a5f-c5cd-450f-a04c-33e4242e3c12]Traceback (most recent call last):
[MFLOG|0|2025-04-17T18:40:07.976339Z|runtime|75caaca4-2e3c-40e5-b846-4dcf8607821a]  File "/opt/anaconda3/envs/mlops/lib/python3.12/site-packages/sklearn/model_selection/_validation.py", line 888, in _fit_and_score
[MFLOG|0|2025-04-17T18:40:07.976356Z|runtime|073352fa-fe82-40e5-8d98-915ba5d4b088]    estimator.fit(X_train, y_train, fit_params)
[MFLOG|0|2025-04-17T18:40:07.976373Z|runtime|133bcf31-432b-472b-ab78-4e46f55b6189]  File "/opt/anaconda3/envs/mlops/lib/python3.12/site-packages/sklearn/base.py", line 1473, in wrapper
[MFLOG|0|2025-04-17T18:40:07.976388Z|runtime|f323728b-d65f-4389-a35e-92cb796e5fef]    return fit_method(estimator, args, kwargs)
[MFLOG|0|2025-04-17T18:40:07.976404Z|runtime|86a64b28-10b8-4aac-9afe-c7ae87cb57b6]           ^^^^^^^^^^^^^^^^^^^^^^^^^^^^^^^^^^^^^^
[MFLOG|0|2025-04-17T18:40:07.976421Z|runtime|ce92e90c-5934-41ee-8893-f226c8c8f441]  File "/opt/anaconda3/envs/mlops/lib/python3.12/site-packages/sklearn/ensemble/_forest.py", line 421, in fit
[MFLOG|0|2025-04-17T18:40:07.976443Z|runtime|b795a6e4-3eb9-44ca-8a3c-4ffad95a131c]    y, expanded_class_weight = self._validate_y_class_weight(y)
[MFLOG|0|2025-04-17T18:40:07.976459Z|runtime|fd63e1a0-f209-4993-b0ed-f2c22469d45a]                               ^^^^^^^^^^^^^^^^^^^^^^^^^^^^^^^^
[MFLOG|0|2025-04-17T18:40:07.976477Z|runtime|3002e0a8-6827-4b36-97e6-5927c4e88bf3]  File "/opt/anaconda3/envs/mlops/lib/python3.12/site-packages/sklearn/ensemble/_forest.py", line 831, in _validate_y_class_weight
[MFLOG|0|2025-04-17T18:40:07.976494Z|runtime|21cfff15-821a-444b-9464-bd94de04f275]    check_classification_targets(y)
[MFLOG|0|2025-04-17T18:40:07.976511Z|runtime|9006f3d5-b8b3-48b8-b0b6-ffb3c7d081e2]  File "/opt/anaconda3/envs/mlops/lib/python3.12/site-packages/sklearn/utils/multiclass.py", line 219, in check_classification_targets
[MFLOG|0|2025-04-17T18:40:07.976527Z|runtime|9a9cd4bc-c774-44d8-8764-827caeea8665]    raise ValueError(
[MFLOG|0|2025-04-17T18:40:07.976545Z|runtime|04f72106-5695-44ad-9534-d2a2db1bd2b8]ValueError: Unknown label type: continuous. Maybe you are trying to fit a classifier, which expects discrete classes on a regression target with continuous values.
[MFLOG|0|2025-04-17T18:40:07.976563Z|runtime|159f89b1-fc94-4ae2-ae22-b9d0dc3208d5]
[MFLOG|0|2025-04-17T18:40:07.976580Z|runtime|89f035d2-9331-4770-9e95-d1ac052ad61f]
[MFLOG|0|2025-04-17T18:40:07.976892Z|runtime|fee86939-3d1a-4791-acb5-9058cde09fd5]Task failed.