[MFLOG|0|2025-04-17T20:11:48.036909Z|runtime|e27b3803-3f89-4337-9899-b89866d08dcb]<flow ScoringFlow step output_predictions> failed:
[MFLOG|0|2025-04-17T20:11:48.040661Z|runtime|d29db8b4-b2c4-4d1c-ab30-5d9d6a94b641]    Internal error
[MFLOG|0|2025-04-17T20:11:48.041463Z|runtime|664a2303-79c6-4775-be7d-a167e38f4d46]Traceback (most recent call last):
[MFLOG|0|2025-04-17T20:11:48.041494Z|runtime|ae1ff38f-1e83-4394-841c-63ae50488397]  File "/opt/anaconda3/envs/mlops/lib/python3.12/site-packages/metaflow/cli.py", line 611, in main
[MFLOG|0|2025-04-17T20:11:48.041517Z|runtime|5be5eca7-dc42-47c0-a98e-271d26a6cb99]    start(auto_envvar_prefix="METAFLOW", obj=state)
[MFLOG|0|2025-04-17T20:11:48.041541Z|runtime|20f29fcd-5fab-4090-80ff-325e0626878e]  File "/opt/anaconda3/envs/mlops/lib/python3.12/site-packages/metaflow/_vendor/click/core.py", line 829, in __call__
[MFLOG|0|2025-04-17T20:11:48.041569Z|runtime|53b15b1e-de8c-44dc-8e51-c79d4e31bebb]    return self.main(args, kwargs)
[MFLOG|0|2025-04-17T20:11:48.143273Z|runtime|df167857-e192-4955-8de1-a4d3725cb45b]           ^^^^^^^^^^^^^^^^^^^^^^^^^^
[MFLOG|0|2025-04-17T20:11:48.143372Z|runtime|4173be98-c77d-4d0d-a751-5b14dda6778a]  File "/opt/anaconda3/envs/mlops/lib/python3.12/site-packages/metaflow/_vendor/click/core.py", line 782, in main
[MFLOG|0|2025-04-17T20:11:48.143399Z|runtime|bee8ba1c-5a75-4df0-af5b-8e1d9e9cddc4]    rv = self.invoke(ctx)
[MFLOG|0|2025-04-17T20:11:48.143423Z|runtime|0929a7a3-193c-4b5b-9480-e2ad965c9189]         ^^^^^^^^^^^^^^^^
[MFLOG|0|2025-04-17T20:11:48.143445Z|runtime|3ea7b098-d9bb-47cf-9e0a-dc259ecee0d3]  File "/opt/anaconda3/envs/mlops/lib/python3.12/site-packages/metaflow/cli_components/utils.py", line 69, in invoke
[MFLOG|0|2025-04-17T20:11:48.143465Z|runtime|8bf3329e-1831-48d9-8ee3-2d2967cd0eba]    return _process_result(sub_ctx.command.invoke(sub_ctx))
[MFLOG|0|2025-04-17T20:11:48.143483Z|runtime|b37407dc-635b-4ce2-94c8-ec38828f411c]                           ^^^^^^^^^^^^^^^^^^^^^^^^^^^^^^^
[MFLOG|0|2025-04-17T20:11:48.143503Z|runtime|b7d5a394-a642-49cc-80db-3152bd01a882]  File "/opt/anaconda3/envs/mlops/lib/python3.12/site-packages/metaflow/_vendor/click/core.py", line 1066, in invoke
[MFLOG|0|2025-04-17T20:11:48.143521Z|runtime|60fd8376-0a8c-45ee-af60-741ba7a8a0b0]    return ctx.invoke(self.callback, ctx.params)
[MFLOG|0|2025-04-17T20:11:48.143540Z|runtime|7304070e-cbdf-419c-a16f-9afd6e12d405]           ^^^^^^^^^^^^^^^^^^^^^^^^^^^^^^^^^^^^^^^
[MFLOG|0|2025-04-17T20:11:48.143561Z|runtime|a45c0ae8-870e-4db7-977b-3c3fd2e5c2f9]  File "/opt/anaconda3/envs/mlops/lib/python3.12/site-packages/metaflow/_vendor/click/core.py", line 610, in invoke
[MFLOG|0|2025-04-17T20:11:48.143579Z|runtime|f4a6594a-6f86-434a-adbb-ae505ffcf3a4]    return callback(args, kwargs)
[MFLOG|0|2025-04-17T20:11:48.143597Z|runtime|c2f66237-3897-4829-80e6-e24a50303f86]           ^^^^^^^^^^^^^^^^^^^^^^^^^
[MFLOG|0|2025-04-17T20:11:48.143615Z|runtime|1bbed0ac-4286-4a85-90cd-9c2b3c7b8706]  File "/opt/anaconda3/envs/mlops/lib/python3.12/site-packages/metaflow/tracing/__init__.py", line 27, in wrapper_func
[MFLOG|0|2025-04-17T20:11:48.143634Z|runtime|90876727-6cd9-4624-a6e4-8663cd5a741a]    return func(args, kwargs)
[MFLOG|0|2025-04-17T20:11:48.143654Z|runtime|29b7428d-0b88-4073-9a8b-ec3896934068]           ^^^^^^^^^^^^^^^^^^^^^
[MFLOG|0|2025-04-17T20:11:48.143672Z|runtime|4e7e48c2-4a32-4fdb-a5e2-006c8116b527]  File "/opt/anaconda3/envs/mlops/lib/python3.12/site-packages/metaflow/_vendor/click/decorators.py", line 21, in new_func
[MFLOG|0|2025-04-17T20:11:48.143690Z|runtime|a99405e0-0583-44d6-99ba-b50534b0c456]    return f(get_current_context(), args, kwargs)
[MFLOG|0|2025-04-17T20:11:48.143709Z|runtime|57f72615-c55f-4ec6-a90d-792d514175a0]           ^^^^^^^^^^^^^^^^^^^^^^^^^^^^^^^^^^^^^^^^^
[MFLOG|0|2025-04-17T20:11:48.143725Z|runtime|8d28979c-f5e2-4077-9ef6-77d4bbfe21c5]  File "/opt/anaconda3/envs/mlops/lib/python3.12/site-packages/metaflow/cli_components/step_cmd.py", line 167, in step
[MFLOG|0|2025-04-17T20:11:48.143745Z|runtime|b153bd48-17ae-4b4e-b4e7-cf3762d87480]    task.run_step(
[MFLOG|0|2025-04-17T20:11:48.143762Z|runtime|2aa8ac3e-92d8-473f-af09-703f556f0aef]  File "/opt/anaconda3/envs/mlops/lib/python3.12/site-packages/metaflow/task.py", line 672, in run_step
[MFLOG|0|2025-04-17T20:11:48.143778Z|runtime|5dae90da-5771-4dca-9f98-4a72081e536c]    self._exec_step_function(step_func)
[MFLOG|0|2025-04-17T20:11:48.143796Z|runtime|eff68258-5c52-4f57-bf0d-e793524cab8b]  File "/opt/anaconda3/envs/mlops/lib/python3.12/site-packages/metaflow/task.py", line 62, in _exec_step_function
[MFLOG|0|2025-04-17T20:11:48.143812Z|runtime|325846b6-dcaf-4571-ab30-8cfaf1ed0a39]    step_function()
[MFLOG|0|2025-04-17T20:11:48.143828Z|runtime|f387bae1-1ea5-4578-b06d-9175a2ae4d55]  File "/Users/jahnavipaliwal/Desktop/ML_Ops/MLOps/Labs/Lab6/src/scoring.py", line 33, in output_predictions
[MFLOG|0|2025-04-17T20:11:48.143862Z|runtime|050482dd-54de-4315-9740-1dabce5a0c70]    results_df.to_csv('../../data/processed/predictions.csv', index=False)
[MFLOG|0|2025-04-17T20:11:48.143878Z|runtime|c96269f2-ba29-4d5b-90fe-b684c67b68bc]  File "/opt/anaconda3/envs/mlops/lib/python3.12/site-packages/pandas/util/_decorators.py", line 333, in wrapper
[MFLOG|0|2025-04-17T20:11:48.143900Z|runtime|833e2790-e2e7-4f06-a017-0c502ef18d64]    return func(args, kwargs)
[MFLOG|0|2025-04-17T20:11:48.143916Z|runtime|5988c5b1-5542-4f85-858b-76309e9a1d9d]           ^^^^^^^^^^^^^^^^^^^^^
[MFLOG|0|2025-04-17T20:11:48.143931Z|runtime|b017d509-4a40-44f7-b68c-87b3527c014e]  File "/opt/anaconda3/envs/mlops/lib/python3.12/site-packages/pandas/core/generic.py", line 3967, in to_csv
[MFLOG|0|2025-04-17T20:11:48.143947Z|runtime|d923ab31-7680-4f73-8d0a-2b30958d6530]    return DataFrameRenderer(formatter).to_csv(
[MFLOG|0|2025-04-17T20:11:48.143967Z|runtime|52e07a27-8d77-4212-bed2-aafea8c9cb1f]           ^^^^^^^^^^^^^^^^^^^^^^^^^^^^^^^^^^^^
[MFLOG|0|2025-04-17T20:11:48.143983Z|runtime|7ef54abc-e637-474e-ab17-c7f9d04552d0]  File "/opt/anaconda3/envs/mlops/lib/python3.12/site-packages/pandas/io/formats/format.py", line 1014, in to_csv
[MFLOG|0|2025-04-17T20:11:48.144004Z|runtime|6dbaf45b-8a5d-4f2e-9a81-c08f00cb0619]    csv_formatter.save()
[MFLOG|0|2025-04-17T20:11:48.144028Z|runtime|239d7a08-2a28-4d8a-8aad-ebb59eadc698]  File "/opt/anaconda3/envs/mlops/lib/python3.12/site-packages/pandas/io/formats/csvs.py", line 251, in save
[MFLOG|0|2025-04-17T20:11:48.144044Z|runtime|6ebae27d-8d7b-499d-84d1-ffb3c1c666c0]    with get_handle(
[MFLOG|0|2025-04-17T20:11:48.144063Z|runtime|6ebe9bba-e384-4b0f-a422-de712693938f]         ^^^^^^^^^^^
[MFLOG|0|2025-04-17T20:11:48.144079Z|runtime|71dd844b-d4e5-4edf-a1dc-951f5d3f180b]  File "/opt/anaconda3/envs/mlops/lib/python3.12/site-packages/pandas/io/common.py", line 749, in get_handle
[MFLOG|0|2025-04-17T20:11:48.144095Z|runtime|08bf71d3-4c2a-4655-a77b-801812b151f6]    check_parent_directory(str(handle))
[MFLOG|0|2025-04-17T20:11:48.144113Z|runtime|e8d64be3-2303-41cd-a1d6-a357afd1dd30]  File "/opt/anaconda3/envs/mlops/lib/python3.12/site-packages/pandas/io/common.py", line 616, in check_parent_directory
[MFLOG|0|2025-04-17T20:11:48.144131Z|runtime|2241070c-4a02-427a-b520-20f201b9e2e8]    raise OSError(rf"Cannot save file into a non-existent directory: '{parent}'")
[MFLOG|0|2025-04-17T20:11:48.144149Z|runtime|da5f2934-ab4a-40cf-bdde-d6e8d1f35780]OSError: Cannot save file into a non-existent directory: '../../data/processed'
[MFLOG|0|2025-04-17T20:11:48.144172Z|runtime|0b70e302-43a8-47ad-9089-0be97741722f]
[MFLOG|0|2025-04-17T20:11:48.144474Z|runtime|55e73d28-42fd-40e5-be82-d39deff6c8f0]Task failed.