[MFLOG|0|2025-04-17T18:37:13.020122Z|runtime|2ecfc344-341e-48f5-b2d2-2074c112719f]<flow TrainingFlow step process_data> failed:
[MFLOG|0|2025-04-17T18:37:13.240605Z|runtime|9a9ba383-1cf1-44e8-a1c9-62764c2e35e1]    Internal error
[MFLOG|0|2025-04-17T18:37:13.241417Z|runtime|18876336-0f0e-402c-be2b-ab844a9b7cc8]Traceback (most recent call last):
[MFLOG|0|2025-04-17T18:37:13.241467Z|runtime|b3d37fc8-eef5-498e-8197-18d9746508e0]  File "/opt/anaconda3/envs/mlops/lib/python3.12/site-packages/metaflow/cli.py", line 611, in main
[MFLOG|0|2025-04-17T18:37:13.241502Z|runtime|405146ac-4371-45f7-b5b2-5df34dd36bf5]    start(auto_envvar_prefix="METAFLOW", obj=state)
[MFLOG|0|2025-04-17T18:37:13.241531Z|runtime|76b88d79-04ba-41dc-9593-5c0142104948]  File "/opt/anaconda3/envs/mlops/lib/python3.12/site-packages/metaflow/_vendor/click/core.py", line 829, in __call__
[MFLOG|0|2025-04-17T18:37:13.241555Z|runtime|133e3cdd-bd9f-4195-84f1-502b795fdf7c]    return self.main(args, kwargs)
[MFLOG|0|2025-04-17T18:37:13.361353Z|runtime|24030eb7-23b0-4f6e-8494-ef896478396d]           ^^^^^^^^^^^^^^^^^^^^^^^^^^
[MFLOG|0|2025-04-17T18:37:13.361461Z|runtime|fef66348-f3df-4a1a-b32e-40b327b4f3cd]  File "/opt/anaconda3/envs/mlops/lib/python3.12/site-packages/metaflow/_vendor/click/core.py", line 782, in main
[MFLOG|0|2025-04-17T18:37:13.361495Z|runtime|63038ceb-ca7e-4c1f-bfec-29b2d9ba43e6]    rv = self.invoke(ctx)
[MFLOG|0|2025-04-17T18:37:13.361522Z|runtime|beccd58d-9781-4152-94d1-30fc2eaaf99d]         ^^^^^^^^^^^^^^^^
[MFLOG|0|2025-04-17T18:37:13.361544Z|runtime|526dcbd8-d0f3-4b79-903d-2920228d35b4]  File "/opt/anaconda3/envs/mlops/lib/python3.12/site-packages/metaflow/cli_components/utils.py", line 69, in invoke
[MFLOG|0|2025-04-17T18:37:13.361565Z|runtime|b1787cf9-cc51-4731-aa78-b79a8dc7fad5]    return _process_result(sub_ctx.command.invoke(sub_ctx))
[MFLOG|0|2025-04-17T18:37:13.361588Z|runtime|e734e102-ec8a-4ca5-8b7a-c851b63589dc]                           ^^^^^^^^^^^^^^^^^^^^^^^^^^^^^^^
[MFLOG|0|2025-04-17T18:37:13.361610Z|runtime|47b1b77c-69aa-49f1-88f8-320a1770a6b2]  File "/opt/anaconda3/envs/mlops/lib/python3.12/site-packages/metaflow/_vendor/click/core.py", line 1066, in invoke
[MFLOG|0|2025-04-17T18:37:13.361631Z|runtime|83aa9ee0-7f15-4e16-a574-b17fc1209e6a]    return ctx.invoke(self.callback, ctx.params)
[MFLOG|0|2025-04-17T18:37:13.361656Z|runtime|29a82c42-7e40-4334-98a4-06267c7aff77]           ^^^^^^^^^^^^^^^^^^^^^^^^^^^^^^^^^^^^^^^
[MFLOG|0|2025-04-17T18:37:13.361677Z|runtime|08a9e894-b944-4567-899b-e66fce74343d]  File "/opt/anaconda3/envs/mlops/lib/python3.12/site-packages/metaflow/_vendor/click/core.py", line 610, in invoke
[MFLOG|0|2025-04-17T18:37:13.361697Z|runtime|f4ab55bb-8730-465b-b89a-a0569ece4114]    return callback(args, kwargs)
[MFLOG|0|2025-04-17T18:37:13.361716Z|runtime|c7ed005c-bf34-40e7-a861-c2c5ce9268b4]           ^^^^^^^^^^^^^^^^^^^^^^^^^
[MFLOG|0|2025-04-17T18:37:13.361734Z|runtime|6099b55d-3e15-4180-a04e-03185b8b4974]  File "/opt/anaconda3/envs/mlops/lib/python3.12/site-packages/metaflow/tracing/__init__.py", line 27, in wrapper_func
[MFLOG|0|2025-04-17T18:37:13.361756Z|runtime|b794153c-d8f5-415e-b22b-b053aabb7479]    return func(args, kwargs)
[MFLOG|0|2025-04-17T18:37:13.361774Z|runtime|dca3abe3-a911-478c-be3d-12a3f9d3b3fb]           ^^^^^^^^^^^^^^^^^^^^^
[MFLOG|0|2025-04-17T18:37:13.361793Z|runtime|0e51be38-768f-472d-a0d7-de3f6d6a89ca]  File "/opt/anaconda3/envs/mlops/lib/python3.12/site-packages/metaflow/_vendor/click/decorators.py", line 21, in new_func
[MFLOG|0|2025-04-17T18:37:13.361817Z|runtime|c87590e0-621c-4f5e-abb7-96ec8932b8b5]    return f(get_current_context(), args, kwargs)
[MFLOG|0|2025-04-17T18:37:13.361835Z|runtime|e486e1d2-7e8e-4b93-b56f-2aa37d9d61c9]           ^^^^^^^^^^^^^^^^^^^^^^^^^^^^^^^^^^^^^^^^^
[MFLOG|0|2025-04-17T18:37:13.361853Z|runtime|60229afb-c18d-4f15-86ce-ec1c6d46716d]  File "/opt/anaconda3/envs/mlops/lib/python3.12/site-packages/metaflow/cli_components/step_cmd.py", line 167, in step
[MFLOG|0|2025-04-17T18:37:13.361873Z|runtime|19a0aaaf-6606-4404-80b4-014a286074fe]    task.run_step(
[MFLOG|0|2025-04-17T18:37:13.361892Z|runtime|e3f11769-8972-4f2a-bf95-f9e72f18e50c]  File "/opt/anaconda3/envs/mlops/lib/python3.12/site-packages/metaflow/task.py", line 672, in run_step
[MFLOG|0|2025-04-17T18:37:13.361912Z|runtime|d3a807ad-5b4c-47d1-b16e-da1bc9bd14b8]    self._exec_step_function(step_func)
[MFLOG|0|2025-04-17T18:37:13.361931Z|runtime|1d854eb6-78e8-4a06-9b4a-569ab0436458]  File "/opt/anaconda3/envs/mlops/lib/python3.12/site-packages/metaflow/task.py", line 62, in _exec_step_function
[MFLOG|0|2025-04-17T18:37:13.361953Z|runtime|7bd2622c-6396-49db-8a57-2e3e0908d066]    step_function()
[MFLOG|0|2025-04-17T18:37:13.361974Z|runtime|a7ba0b06-7ce2-4010-95e2-1ef889ee8249]  File "/Users/jahnavipaliwal/Desktop/ML_Ops/MLOps/Labs/Lab6/src/trainingflow.py", line 22, in process_data
[MFLOG|0|2025-04-17T18:37:13.361996Z|runtime|933c2111-e926-4e4d-9834-48968de52a3e]    self.X, self.y = dataprocessing.feature_transform(self.df)
[MFLOG|0|2025-04-17T18:37:13.362013Z|runtime|433ee1ac-12fb-4fa5-bbd9-7629040f11dd]                     ^^^^^^^^^^^^^^^^^^^^^^^^^^^^^^^^^^^^^^^^^
[MFLOG|0|2025-04-17T18:37:13.362031Z|runtime|9cc2b483-879a-439d-beb0-94ebdc05f57c]  File "/Users/jahnavipaliwal/Desktop/ML_Ops/MLOps/Labs/Lab6/src/dataprocessing.py", line 7, in feature_transform
[MFLOG|0|2025-04-17T18:37:13.362048Z|runtime|e1c872ed-1d69-467b-b053-f7651060574c]    X = df.drop('target', axis=1)
[MFLOG|0|2025-04-17T18:37:13.362066Z|runtime|98d74e95-65b5-4ae3-8856-aa57baee3b2f]        ^^^^^^^^^^^^^^^^^^^^^^^^^
[MFLOG|0|2025-04-17T18:37:13.362084Z|runtime|d96fcc9c-51d2-453d-8509-d1c6d66ab4db]  File "/opt/anaconda3/envs/mlops/lib/python3.12/site-packages/pandas/core/frame.py", line 5581, in drop
[MFLOG|0|2025-04-17T18:37:13.362101Z|runtime|674b54a3-b980-48f0-9601-d8c88b873a2b]    return super().drop(
[MFLOG|0|2025-04-17T18:37:13.362121Z|runtime|002301cf-4980-481a-9df4-c2b580a9d5c1]           ^^^^^^^^^^^^^
[MFLOG|0|2025-04-17T18:37:13.362139Z|runtime|8d3226d5-30db-42aa-8c86-1e4aba26998b]  File "/opt/anaconda3/envs/mlops/lib/python3.12/site-packages/pandas/core/generic.py", line 4788, in drop
[MFLOG|0|2025-04-17T18:37:13.362156Z|runtime|f49decad-d023-4e11-9468-d80a886e6c86]    obj = obj._drop_axis(labels, axis, level=level, errors=errors)
[MFLOG|0|2025-04-17T18:37:13.362174Z|runtime|0005d44b-ea22-4ccd-a447-74ef21c348a7]          ^^^^^^^^^^^^^^^^^^^^^^^^^^^^^^^^^^^^^^^^^^^^^^^^^^^^^^^^
[MFLOG|0|2025-04-17T18:37:13.362192Z|runtime|9a2d330a-630a-4b4a-a79c-1a9f604d21a5]  File "/opt/anaconda3/envs/mlops/lib/python3.12/site-packages/pandas/core/generic.py", line 4830, in _drop_axis
[MFLOG|0|2025-04-17T18:37:13.362210Z|runtime|0b51d983-6501-463e-b82c-c4814a9e578e]    new_axis = axis.drop(labels, errors=errors)
[MFLOG|0|2025-04-17T18:37:13.362227Z|runtime|48b11aac-2275-444c-b32c-2257a72c25e3]               ^^^^^^^^^^^^^^^^^^^^^^^^^^^^^^^^
[MFLOG|0|2025-04-17T18:37:13.362245Z|runtime|429fff25-b1d9-4994-aab2-bb58f05373cd]  File "/opt/anaconda3/envs/mlops/lib/python3.12/site-packages/pandas/core/indexes/base.py", line 7070, in drop
[MFLOG|0|2025-04-17T18:37:13.362262Z|runtime|770a87c8-fe06-41db-a6dc-171184ad0593]    raise KeyError(f"{labels[mask].tolist()} not found in axis")
[MFLOG|0|2025-04-17T18:37:13.362279Z|runtime|81f57ad1-f464-4e55-92bc-ea29914f8de7]KeyError: "['target'] not found in axis"
[MFLOG|0|2025-04-17T18:37:13.362298Z|runtime|603a5796-20e3-451d-9068-2c69530a832f]
[MFLOG|0|2025-04-17T18:37:13.362635Z|runtime|860eeb3f-6fce-40d4-9a7b-682b93694199]Task failed.