[MFLOG|0|2025-04-17T18:00:32.416231Z|runtime|47e1d667-53d3-46f0-92a0-51315d3cf8a8]<flow TrainingFlow step start> failed:
[MFLOG|0|2025-04-17T18:00:32.419432Z|runtime|99eac422-c235-431a-9cbc-219dc48c76f5]    Internal error
[MFLOG|0|2025-04-17T18:00:32.420279Z|runtime|ee51bbbd-09ad-4ef3-a9be-f2d5c3bfab00]Traceback (most recent call last):
[MFLOG|0|2025-04-17T18:00:32.420314Z|runtime|5d370680-89a3-4d2a-8706-f1c7c31298f8]  File "/opt/anaconda3/envs/mlops/lib/python3.12/site-packages/metaflow/cli.py", line 611, in main
[MFLOG|0|2025-04-17T18:00:32.420342Z|runtime|7c7a7db7-f4d3-470e-bcbe-18d9c42d0011]    start(auto_envvar_prefix="METAFLOW", obj=state)
[MFLOG|0|2025-04-17T18:00:32.420381Z|runtime|7ca89ea9-b9c9-4898-a807-f264d2bce9cf]  File "/opt/anaconda3/envs/mlops/lib/python3.12/site-packages/metaflow/_vendor/click/core.py", line 829, in __call__
[MFLOG|0|2025-04-17T18:00:32.420405Z|runtime|823c450f-3b71-4962-b973-0fae20d6fd5c]    return self.main(args, kwargs)
[MFLOG|0|2025-04-17T18:00:32.528202Z|runtime|f498bad4-20ba-49e2-ad9c-94cc58d72f44]           ^^^^^^^^^^^^^^^^^^^^^^^^^^
[MFLOG|0|2025-04-17T18:00:32.528339Z|runtime|d2d22874-4efb-4c0b-bd1d-f34146e4f8cb]  File "/opt/anaconda3/envs/mlops/lib/python3.12/site-packages/metaflow/_vendor/click/core.py", line 782, in main
[MFLOG|0|2025-04-17T18:00:32.528368Z|runtime|ae7711fc-c1ab-4a7c-a1d2-edc04fb684e6]    rv = self.invoke(ctx)
[MFLOG|0|2025-04-17T18:00:32.528388Z|runtime|648cf984-92fd-43bc-89e1-d37485f52a5a]         ^^^^^^^^^^^^^^^^
[MFLOG|0|2025-04-17T18:00:32.528408Z|runtime|cbfc56d2-7aa2-4464-a61a-dfa004d75a4d]  File "/opt/anaconda3/envs/mlops/lib/python3.12/site-packages/metaflow/cli_components/utils.py", line 69, in invoke
[MFLOG|0|2025-04-17T18:00:32.528430Z|runtime|daa486de-f483-4bf3-a4cc-03d1b24ad94f]    return _process_result(sub_ctx.command.invoke(sub_ctx))
[MFLOG|0|2025-04-17T18:00:32.528454Z|runtime|169ea082-8ad8-4d45-830c-43207e48f3b5]                           ^^^^^^^^^^^^^^^^^^^^^^^^^^^^^^^
[MFLOG|0|2025-04-17T18:00:32.528473Z|runtime|a80779c4-7c8e-4c30-89e3-f7b1753878d8]  File "/opt/anaconda3/envs/mlops/lib/python3.12/site-packages/metaflow/_vendor/click/core.py", line 1066, in invoke
[MFLOG|0|2025-04-17T18:00:32.528492Z|runtime|1f5862ee-7ec0-4545-87d6-fa70635620b5]    return ctx.invoke(self.callback, ctx.params)
[MFLOG|0|2025-04-17T18:00:32.528510Z|runtime|7b42feb4-2e3c-45a6-bb85-d5993d7db947]           ^^^^^^^^^^^^^^^^^^^^^^^^^^^^^^^^^^^^^^^
[MFLOG|0|2025-04-17T18:00:32.528527Z|runtime|c517b55c-6c9d-43bf-89b6-988594c00058]  File "/opt/anaconda3/envs/mlops/lib/python3.12/site-packages/metaflow/_vendor/click/core.py", line 610, in invoke
[MFLOG|0|2025-04-17T18:00:32.528544Z|runtime|8c31a32d-f5fc-4b14-ad75-11b46bc31a73]    return callback(args, kwargs)
[MFLOG|0|2025-04-17T18:00:32.528566Z|runtime|37646cc5-9e37-40aa-8acc-7a72a957db78]           ^^^^^^^^^^^^^^^^^^^^^^^^^
[MFLOG|0|2025-04-17T18:00:32.528581Z|runtime|ece1bb9f-2c09-4a45-81a5-3e303cc749d1]  File "/opt/anaconda3/envs/mlops/lib/python3.12/site-packages/metaflow/tracing/__init__.py", line 27, in wrapper_func
[MFLOG|0|2025-04-17T18:00:32.528600Z|runtime|3b8e577b-ae9b-4a95-b43a-e307e494d15b]    return func(args, kwargs)
[MFLOG|0|2025-04-17T18:00:32.528618Z|runtime|9b296cca-579c-46ab-a6a3-b7c3869960c5]           ^^^^^^^^^^^^^^^^^^^^^
[MFLOG|0|2025-04-17T18:00:32.528634Z|runtime|92e8cae4-5aef-499d-9aa9-f1f059f6c9f1]  File "/opt/anaconda3/envs/mlops/lib/python3.12/site-packages/metaflow/_vendor/click/decorators.py", line 21, in new_func
[MFLOG|0|2025-04-17T18:00:32.528651Z|runtime|fd8a455b-80fe-48e6-a689-fdab7f89a7ee]    return f(get_current_context(), args, kwargs)
[MFLOG|0|2025-04-17T18:00:32.528666Z|runtime|03e2f497-0bee-43c6-abc4-b12affd10e16]           ^^^^^^^^^^^^^^^^^^^^^^^^^^^^^^^^^^^^^^^^^
[MFLOG|0|2025-04-17T18:00:32.528683Z|runtime|b04f1aa2-7d3a-49cf-b6be-4d276d6a15ff]  File "/opt/anaconda3/envs/mlops/lib/python3.12/site-packages/metaflow/cli_components/step_cmd.py", line 167, in step
[MFLOG|0|2025-04-17T18:00:32.528701Z|runtime|beab4e90-9844-46b1-932b-5507aa2e560b]    task.run_step(
[MFLOG|0|2025-04-17T18:00:32.528718Z|runtime|874b883a-4fc4-41a2-98cd-ff4df929afdd]  File "/opt/anaconda3/envs/mlops/lib/python3.12/site-packages/metaflow/task.py", line 672, in run_step
[MFLOG|0|2025-04-17T18:00:32.528733Z|runtime|82b82ead-f44f-4030-92ec-ee195b853382]    self._exec_step_function(step_func)
[MFLOG|0|2025-04-17T18:00:32.528748Z|runtime|212bd913-6d09-4a61-af57-b7127f8bfbd3]  File "/opt/anaconda3/envs/mlops/lib/python3.12/site-packages/metaflow/task.py", line 62, in _exec_step_function
[MFLOG|0|2025-04-17T18:00:32.528763Z|runtime|00bcd4c0-c86b-4290-8452-4b0c640b59bd]    step_function()
[MFLOG|0|2025-04-17T18:00:32.528780Z|runtime|f875b7bb-0483-49fc-801b-05db188f61a4]  File "/Users/jahnavipaliwal/Desktop/ML_Ops/MLOps/Labs/Lab6/src/trainingflow.py", line 16, in start
[MFLOG|0|2025-04-17T18:00:32.528798Z|runtime|144ef5d5-1bce-4cbd-8431-afdaf9ebe00a]    self.df = pd.read_csv('data/raw/dataset.csv')
[MFLOG|0|2025-04-17T18:00:32.528813Z|runtime|4630a2ea-c27a-4d0b-97b6-cddf62d048a8]              ^^^^^^^^^^^^^^^^^^^^^^^^^^^^^^^^^^^
[MFLOG|0|2025-04-17T18:00:32.528831Z|runtime|c811095d-be73-4095-a490-3b6c3a7b727a]  File "/opt/anaconda3/envs/mlops/lib/python3.12/site-packages/pandas/io/parsers/readers.py", line 1026, in read_csv
[MFLOG|0|2025-04-17T18:00:32.528846Z|runtime|44609309-7d8b-4772-bd9a-d2d923761bd5]    return _read(filepath_or_buffer, kwds)
[MFLOG|0|2025-04-17T18:00:32.528865Z|runtime|40b94216-1fdc-402a-9e5a-4150cc630a45]           ^^^^^^^^^^^^^^^^^^^^^^^^^^^^^^^
[MFLOG|0|2025-04-17T18:00:32.528880Z|runtime|1f64f6b5-8a4f-4623-9a54-68beb81cce9f]  File "/opt/anaconda3/envs/mlops/lib/python3.12/site-packages/pandas/io/parsers/readers.py", line 620, in _read
[MFLOG|0|2025-04-17T18:00:32.528895Z|runtime|767244b6-3d09-470b-9ada-7a172e3c737f]    parser = TextFileReader(filepath_or_buffer, kwds)
[MFLOG|0|2025-04-17T18:00:32.528911Z|runtime|93aa452d-5053-4844-a33c-7f87ca1828d2]             ^^^^^^^^^^^^^^^^^^^^^^^^^^^^^^^^^^^^^^^^^^
[MFLOG|0|2025-04-17T18:00:32.528928Z|runtime|e4f8eb57-aab1-4588-a350-d75c1ca9b7f4]  File "/opt/anaconda3/envs/mlops/lib/python3.12/site-packages/pandas/io/parsers/readers.py", line 1620, in __init__
[MFLOG|0|2025-04-17T18:00:32.528943Z|runtime|157dc8db-aa36-4754-92b5-f8b7fd5b3cba]    self._engine = self._make_engine(f, self.engine)
[MFLOG|0|2025-04-17T18:00:32.528958Z|runtime|241c28c3-f9c9-46c4-ba76-10d1552f700e]                   ^^^^^^^^^^^^^^^^^^^^^^^^^^^^^^^^^
[MFLOG|0|2025-04-17T18:00:32.528974Z|runtime|9fa9e0c8-3034-4158-95e3-d9165ab49be0]  File "/opt/anaconda3/envs/mlops/lib/python3.12/site-packages/pandas/io/parsers/readers.py", line 1880, in _make_engine
[MFLOG|0|2025-04-17T18:00:32.528990Z|runtime|43419a78-785b-40e8-92bf-04f982784035]    self.handles = get_handle(
[MFLOG|0|2025-04-17T18:00:32.529006Z|runtime|43c7244b-1689-4297-b864-1e75c1b04c56]                   ^^^^^^^^^^^
[MFLOG|0|2025-04-17T18:00:32.529023Z|runtime|8f5a5cb2-9f02-41b3-95f2-7535c8706a9c]  File "/opt/anaconda3/envs/mlops/lib/python3.12/site-packages/pandas/io/common.py", line 873, in get_handle
[MFLOG|0|2025-04-17T18:00:32.529039Z|runtime|c10684a1-bbe5-4edc-a5dd-d13f20a765a2]    handle = open(
[MFLOG|0|2025-04-17T18:00:32.529058Z|runtime|2491cdb4-5784-4231-a9cc-e1c2bc5661d2]             ^^^^^
[MFLOG|0|2025-04-17T18:00:32.529075Z|runtime|566e9164-da86-405c-b86d-59a3f2d03a65]FileNotFoundError: [Errno 2] No such file or directory: 'data/raw/dataset.csv'
[MFLOG|0|2025-04-17T18:00:32.529091Z|runtime|f12d26d3-d68a-406f-aa52-08d55f7981e5]
[MFLOG|0|2025-04-17T18:00:32.529418Z|runtime|348fa76a-f6cc-4c88-8326-22433df27b85]Task failed.